Workbook
Name a: #REF!
Name aa: #REF!
Name B: [10]Abstract!#REF!
Name Cft: 0.583333333333333
Name CUM: #REF!
Name Dslab: [4]dlvoid!$H$25
Name G509a55: #REF!
Name _HFL1: #N/A
Name _HFL1: #N/A
Name _HFL1: #N/A
Name _HFL1: #N/A
Name _HFL1: #N/A
Name _HFL1: #N/A
Name _HFL1: #N/A
Name _HFL1: #N/A
Name _HFL1: #N/A
Name _HFL1: #N/A
Name _HFL1: #N/A
Name _HFL1: #N/A
Name _HFL1: #N/A
Name _HFL1: #N/A
Name _HFL1: #N/A
Name _HFL1: #N/A
Name _HFL1: #N/A
Name _HFL1: #N/A
Name _HFL1: #N/A
Name _HFL1: #N/A
Name _HFL1: #REF!
Name HLB: #N/A
Name HLB: #N/A
Name HLB: #N/A
Name HLB: #N/A
Name HLB: #N/A
Name HLB: #N/A
Name HLB: #N/A
Name HLB: #N/A
Name HLB: #N/A
Name HLB: #N/A
Name HLB: #N/A
Name HLB: #N/A
Name HLB: #N/A
Name HLB: #N/A
Name HLB: #N/A
Name HLB: #N/A
Name HLB: #N/A
Name HLB: #N/A
Name HLB: #N/A
Name HLB: #N/A
Name HLB: #REF!
Name L_Bhisti: [11]Labour!$D$3
Name L_BitumenSprayer: [11]Labour!$D$4
Name L_Blacksmith: [11]Labour!$D$5
Name L_Blaster: [11]Labour!$D$6
Name L_Carpenter_1stClass: [11]Labour!$D$7
Name L_ChipsSpreader: [11]Labour!$D$8
Name L_Chiseller: [11]Labour!$D$9
Name L_Dresser_Skilled: [11]Labour!$D$10
Name L_Driller: [11]Labour!$D$11
Name L_Electrician_Lineman: [11]Labour!$D$12
Name L_Fitter: [11]Labour!$D$13

Sheet INDEX
A4: DESIGN OF SUBMERSIBLE SKEW BRIDGE ACROSS BEDACH RIVER
A6: INDEX
A8: S.No | B8: Particulars | C8: Page
A9: 1 | B9: Preamble
A10: 2 | B10: Hydraulic Design
A11: 3 | B11: Stability Check for Pier in Different Load Cases
A12: 4 | B12: Computation of Reinforcement in Pier
A13: 5 | B13: Design of Pier Footing
A14: 6 | B14: Design of Pier Footing Cap
A15: 7 | B15: Stability Check for Abutment in Different Load Cases
A16: 8 | B16: Design of Abutment Footing
A17: 9 | B17: Cross Sections & L Section of the River
A18: 10 | B18: Geotechnical Investigation Report
A19: 11 | B19: General Arrangement Drawing
A20: 12 | B20: Details of Pier Complete Drawing
... A27: 19 | B27: Detailed Progress Report

Sheet INSERT- HYDRAULICS

Sheet afflux calculation
A1: DESIGN OF SUBMERSIBLE BRIDGE
A2: Name Of Work :- Construction of Submersible Bridge on ON KHERWARA - JAWAS - SUVERI ROAD IN KM 9/000, ACROSS RIVER SOM
A3: Hydraulic Calculation
A4: Computation of Discharge | C4: 1 | D4: Flood calculation by Area Velocity Method (As per Article- 5 of IRC SP-13)
A5: Q | B5: = | C5: A x V | F5: Where
A6: A | B6: = | C6: =HYDRAULICS!$C$29 -> 490.3 | D6: m2 | G6: A = | H6: Cross sectional area in m2
A7: P | B7: = | C7: =HYDRAULICS!$C$30 -> 190.70731 | D7: m | G7: P = | H7: Perimeter calculated in m
A8: S | B8: = | C8: 1 | D8: IN | E8: =HYDRAULICS!$C$33 -> 960 | G8: S = | H8: Slope as per drain LS taken at
H9: Proposal site
A10: n | B10: = | C10: =HYDRAULICS!$C$32 -> 0.033 | G10: n = | H10: Rugosity coefficient
H11: (As per IRC SP-13)
A12: V | B12: = | C12: I/nx (A/P) 2/3 x(S) 1/2 | G12: V = | H12: Velocity in m/sec.
B13: = | C13: =ROUNDUP(1/C10*((C6/C7)^(2/3)*(1/E8)^0.5),2) -> 1.84 | D13: m/sec.
A14: Q | B14: = | C14: =ROUND(C6*C13,2) -> 902.15 | D14: Cumecs
A15: Linear Water Way Calculation
A16: Regime Surface width of the stream is given by :- | C16: L | D16: = | E16: 4.8 (Q)1/2
B17: = | C17: =ROUNDUP(4.8*(C14)^0.5,2) -> 144.18 | D17: m
A18: Looking to the built up Urban area constraints adopt | C18: 12 | D18: Spans of | F18: 8 | G18: M each.
A19: This will cause contraction and afflux. Calculation is done for the same to fix deck level.
A20: Effective linear water way proposed = | B20: =C18 -> 12 | C20: x | D20: =F18 -> 8 | E20: = | F20: =B20*D20 -> 96 | G20: M
E21: Total | F21: =SUM(F20:F20) -> 96 | G21: M
A22: Scour Depth Calculation
A23: (As per clause no. 703.2.2.1 of IRC : 78.1983)
A24: dsm = | B24: 1.34x (Db2 /Ksf) 1/3 | F24: Where
E25: Db | F25: = | G25: The discharge in Cumecs per meter width
E26: Ksf | F26: = | G26: the silt factor
F27: = | G27: 1.5
A28: Effective linear waterway | B28: = | C28: Width of waterway - Obstructed width of piper
A29: = | B29: =C18*F18-1.2 -> 94.8 | C29: - ( | D29: =B20-1 -> 11 | E29: x | F29: 1.2 | G29: )
A30: = | B30: =B29-(D29*F29) -> 81.6 | C30: m
A31: Db | B31: = | C31: =ROUND(C14,2) -> 902.15 | D31: / | E31: =B30 -> 81.6
B32: = | C32: =ROUNDUP(C31/E31,2) -> 11.06 | D32: Cumecs per metre width
A33: dsm = | B33: =ROUNDUP(1.34* (C32^2 /G27)^(1/3),2) -> 5.82 | C33: m
A34: As per Clause No. 703-2-3-1 of IRC 78-1983 considering Scour at the pier two times of calculated scour depth below the highest flood level. But hard rock is available in foundation so the foundation will be anchored in the rock as per IRC guidelines.
A35: Afflux Calculation
A36: As per IS: 7784 (Part -I) 1975
A37: Molesworth Formula for Afflux
A38: Afflux h = | B38: ((V2/17.85) +0.0152)x(A2/a2-1)
A39: Where,
A40: h | B40: = | C40: afflux in m,
...

Sheet HYDRAULICS
A1: DETERMINATION OF VELOCITY AT PROPOSED SUBMERSIBLE BRIDGE
A2: ='afflux calculation'!A2:H2 -> Name Of Work :- Construction of Submersible Bridge on ON KHERWARA - JAWAS - SUVERI ROAD IN KM 9/000, ACROSS RIVER SOM
A3: AS PER UP-STREAM SECTION
A4: HIGHEST FLOOD LEVEL | F4: 100.6 | G4: M
A5: CHAINAGE | B5: G.L. | C5: DEPTH OF FLOW IN M | D5: LENGTH OF FLOW | E5: AVERAGE DEPTH OF FLOW | F5: CROSS SECTIONAL AREA OF FLOW | G5: WETTED PERIMETER
A6: 0 | B6: 102 | C6: =IF(B6>$F$4,0,$F$4-B6) -> 0 | D6: 0 | E6: 0 | F6: 0 | G6: 0
A7: 10 | B7: 100.95 | C7: =IF(B7>$F$4,0,$F$4-B7) -> 0 | D7: =(A7-A6) -> 10 | E7: =(C7+C6)/2 -> 0 | F7: =D7*E7 -> 0 | G7: =(D7^2+(C6-C7)^2)^0.5 -> 10
A8: 20 | B8: 98.19 | C8: =IF(B8>$F$4,0,$F$4-B8) -> 2.41 | D8: =(A8-A7) -> 10 | E8: =(C8+C7)/2 -> 1.205 | F8: =D8*E8 -> 12.05 | G8: =(D8^2+(C7-C8)^2)^0.5 -> 10.286306
A9: 30 | B9: 97.59 | C9: =IF(B9>$F$4,0,$F$4-B9) -> 3.01 | D9: =(A9-A8) -> 10 | E9: =(C9+C8)/2 -> 2.71 | F9: =D9*E9 -> 27.1 | G9: =(D9^2+(C8-C9)^2)^0.5 -> 10.017984
A10: 40 | B10: 97.21 | C10: =IF(B10>$F$4,0,$F$4-B10) -> 3.39 | D10: =(A10-A9) -> 10 | E10: =(C10+C9)/2 -> 3.2 | F10: =D10*E10 -> 32 | G10: =(D10^2+(C9-C10)^2)^0.5 -> 10.007217
A11: 50 | B11: 96.87 | C11: =IF(B11>$F$4,0,$F$4-B11) -> 3.73 | D11: =(A11-A10) -> 10 | E11: =(C11+C10)/2 -> 3.56 | F11: =D11*E11 -> 35.6 | G11: =(D11^2+(C10-C11)^2)^0.5 -> 10.005778
A12: 60 | B12: 97.96 | C12: =IF(B12>$F$4,0,$F$4-B12) -> 2.64 | D12: =(A12-A11) -> 10 | E12: =(C12+C11)/2 -> 3.185 | F12: =D12*E12 -> 31.85 | G12: =(D12^2+(C11-C12)^2)^0.5 -> 10.05923
A13: 70 | B13: 97.12 | C13: =IF(B13>$F$4,0,$F$4-B13) -> 3.48 | D13: =(A13-A12) -> 10 | E13: =(C13+C12)/2 -> 3.06 | F13: =D13*E13 -> 30.6 | G13: =(D13^2+(C12-C13)^2)^0.5 -> 10.035218
A14: 80 | B14: 96.8 | C14: =IF(B14>$F$4,0,$F$4-B14) -> 3.8 | D14: =(A14-A13) -> 10 | E14: =(C14+C13)/2 -> 3.64 | F14: =D14*E14 -> 36.4 | G14: =(D14^2+(C13-C14)^2)^0.5 -> 10.005119
A15: 90 | B15: 96.47 | C15: =IF(B15>$F$4,0,$F$4-B15) -> 4.13 | D15: =(A15-A14) -> 10 | E15: =(C15+C14)/2 -> 3.965 | F15: =D15*E15 -> 39.65 | G15: =(D15^2+(C14-C15)^2)^0.5 -> 10.005444
A16: 100 | B16: 96.49 | C16: =IF(B16>$F$4,0,$F$4-B16) -> 4.11 | D16: =(A16-A15) -> 10 | E16: =(C16+C15)/2 -> 4.12 | F16: =D16*E16 -> 41.2 | G16: =(D16^2+(C15-C16)^2)^0.5 -> 10.00002
A17: 110 | B17: 97.04 | C17: =IF(B17>$F$4,0,$F$4-B17) -> 3.56 | D17: =(A17-A16) -> 10 | E17: =(C17+C16)/2 -> 3.835 | F17: =D17*E17 -> 38.35 | G17: =(D17^2+(C16-C17)^2)^0.5 -> 10.015114
A18: 120 | B18: 97.29 | C18: =IF(B18>$F$4,0,$F$4-B18) -> 3.31 | D18: =(A18-A17) -> 10 | E18: =(C18+C17)/2 -> 3.435 | F18: =D18*E18 -> 34.35 | G18: =(D18^2+(C17-C18)^2)^0.5 -> 10.003125
... A25: 190 | B25: 102 | C25: =IF(B25>$F$4,0,$F$4-B25) -> 0 | D25: =(A25-A24) -> 10 | E25: =(C25+C24)/2 -> 0 | F25: =D25*E25 -> 0 | G25: =(D25^2+(C24-C25)^2)^0.5 -> 10
C27: TOTAL | D27: =SUM(D6:D26) -> 190 | F27: =SUM(F6:F26) -> 490.3 | G27: =SUM(G6:G26) -> 190.70731
B29: A | C29: =F27 -> 490.3 | D29: SQM
B30: P | C30: =G27 -> 190.70731 | D30: M
B31: R | C31: =C29/C30 -> 2.5709554 | D31: M
B32: N | C32: 0.033
B33: S 1 IN | C33: ='Bed Slope'!J24 -> 960
B34: V | C34: =(1/C32*(C31^(2/3))*((1/C33)^0.5)) -> 1.8354679 | D34: M/SEC
B35: Q | C35: =C29*C34 -> 899.92993 | D35: CUMECS
B36: The design engineer visually observed the river to ascertain the Roughness Coefficient n for the Manning's formula. Upon visual inspection of the river in the vicinity of the proposed bridge site it was found that the River bed surface is good with clean straight banks, no rifts or deep pools however containing some weeds and stones. Roughness Coefficient pertaining to these characteristics is 0.033
B37: Design Discharge = | E37: =C35 -> 899.92993 | F37: =D35 -> CUMECS
A39: Critical Levels
A40: Road top level (RTL) | E40: =ROUND(MAX(E41+E42,F3-'afflux calculation'!B51/2),2) -> 101.6 | G40: M
A41: Average Ground Level(AGL) | E41: 96.6 | G41: M
A42: Average Height Of Bridge | E42: 5 | G42: M
A43: Lowest Nala Bed level (NBL) | E43: =MIN('CROSS SECTION'!B6:B25) -> 96.47 | G43: M
A44: Ordinary flood level (OFL) | E44: =E41+1 -> 97.6 | G44: M
A45: Foundation level (FL) | E45: =E43-3 -> 93.47 | G45: M
A46: Ht. of bridge h= (RTL-NBL) | E46: =E40-E43 -> 5.13 | G46: M
A47: Ht. of bridge H=(RTL-FL) | E47: =E40-E45 -> 8.13 | G47: M
A48: ** Needs Rational Evaluation w.r.t. afflux.
A49: ** Average of GL for points lying below HFL.

Sheet Deck Anchorage
A1: ANCHORAGE OF DECK SLAB TO SUBSTRUCTURE
A2: =HYDRAULICS!A2 -> Name Of Work :- Construction of Submersible Bridge on ON KHERWARA - JAWAS - SUVERI ROAD IN KM 9/000, ACROSS RIVER SOM
B3: In the case of a submersible bridge, the deck slab is near the plane of maximum velocity. To counteract the sliding action due to velocity of flow, loss of weight of slab due to buoyancy, the tilting forces due to eddies and currents and the disturbing forces due to debris or trees floating down the stream , it is necessary to anchor the deck slab to the substructure.
B4: One possible solution to this anchorage is as shown in detailed drawing. The aim in this anchorage is to secure the deck slab to piers or abutments against uplift or lateral thrust and at the same time allow lateral movement due to expansion and contraction due to temperature effects the arrangement will be evident from the sketch given in the detailed drawing.
A5: Check Against Uplift
B6: The uplift force shall be maximum when the flow level is Just at near deck level. | G6: THIS WILL BE IN CASE OF AFFLUX FLOOD LEVEL | L6: ='afflux calculation'!F79 -> 100.83 | M6: M
B7: Total Height | C7: = | D7: ='afflux calculation'!B78 -> 0.23 | E7: M
B8: Maximum Uplift Pressure | C8: = | D8: =D7 -> 0.23 | E8: x | F8: 10 | G8: = | H8: =D8*F8 -> 2.3 | I8: kN/Sqm
B9: Area of Slab under effect of buoyancy | C9: = | D9: ='STABILITY CHECK FOR PIER'!E6 -> 8.8 | E9: x | F9: ='afflux calculation'!C18 -> 12 | G9: = | H9: =D9*F9 -> 105.6 | I9: Sqm
B10: Uplift Force on Slab | C10: = | D10: =H9 -> 105.6 | E10: x | F10: =H8 -> 2.3 | G10: = | H10: =ROUNDUP(D10*F10,2) -> 242.88 | I10: kN
B11: Self Weight of Slab | C11: = | D11: =D9 -> 8.8 | E11: x | F11: =F9 -> 12 | G11: x | H11: 0.75 | I11: x | J11: 24 | K11: = | L11: =D11*F11*H11*J11 -> 1900.8 | M11: kN
B12: Self Weight of Wearing Coat | C12: = | D12: =D11 -> 8.8 | E12: x | F12: =F11 -> 12 | G12: x | H12: 0.075 | I12: x | J12: 24 | K12: = | L12: =D12*F12*H12*J12 -> 190.08 | M12: kN
B13: Footpath | C13: = | D13: 2X10.8 | E13: x | F13: 1.5 | G13: x | H13: 0.5 | I13: x | J13: 0 | K13: = | L13: =2*D12*F13*H13*J13 -> 0 | M13: kN
B14: TOTAL | L14: =SUM(L11:L13) -> 2090.88 | M14: kN
B15: Net Uplift Pressure | C15: = | D15: =H10 -> 242.88 | E15: - | F15: =L14 -> 2090.88 | G15: = | H15: =D15-F15 -> -1848 | I15: kN
H16: < 0 Hence Ok.
A17: Check Against Sliding
B18: Refer Stability Check of Pier
B19: WATER CURRENT IN TRANSVERSE DIRECTION ( ACROSS THE BRIDGE)
B20: As per IRC- II ( 6-1966) clause 213.5 | D20: For V= | E20: ='afflux calculation'!B83 -> 2.67 | F20: m/sec | G20: Maximum velocity being 1.414 x mean velocity | M20: (1.414= Root of 2)
B21: Obstructed Velocity = V Cos 20 0 | C21: = | D21: =E20 -> 2.67 | E21: x | F21: Cos 20 0
C22: = | D22: =D21*COS(20*3.14/180) -> 2.5091409
B23: 2v2 | C23: = | D23: =D22^2*2 -> 12.591576
B24: The soffit of the deck is at HFL | C24: = | D24: ='STABILITY CHECK FOR PIER'!E8 -> 100.6 | E24: ='STABILITY CHECK FOR PIER'!E123 -> M | F24: The afflux Flood Level is | I24: =D24+'afflux calculation'!B78 -> 100.83 | J24: M
B25: DRAG FORCE ON DECK SLAB DUE TO AFFLUX
B26: Area Obstructed | C26: = | D26: =D12 -> 8.8 | E26: x | F26: ='afflux calculation'!B78 -> 0.23 | G26: = | H26: =D26*F26 -> 2.024 | I26: Sqm
B28: Drag Force on Slab | C28: = | D28: 52 | E28: x | F28: k | G28: x | H28: v2 | I28: x | J28: Area Obstructed
C29: = | D29: =D28 -> 52 | E29: x | F29: 1.5 | G29: x | H29: =D23 -> 12.591576 | I29: x | J29: =H26 -> 2.024 | K29: / 100 | L29: = | M29: =D29*F29*H29*J29/100 -> 19.878572 | N29: kN
B31: Dia of Anchor Bars | C31: 32 | D31: mm
B32: Permissible Shear Stress | C32: 190 | D32: N/mm2
B33: Shear Force Resisted by one Anchor Bar = | D33: ( | E33: 0.785 | F33: x | G33: =C31 -> 32 | H33: 2 | I33: /4 )x | J33: =C32 -> 190 | K33: / 1000 | L33: = | M33: =ROUNDUP(E33*C31*C31/4*C32/1000,2) -> 38.19 | N33: kN
B34: Number Of Bars Provided Per slab | C34: 18 | D34: Nos.
B35: Total Shear Resisted | C35: = | D35: =C34 -> 18 | E35: x | F35: =M33 -> 38.19 | G35: = | H35: =D35*F35 -> 687.42 | I35: kN
B36: FACTOR OF SAFETY | C36: = | D36: =H35 -> 687.42 | E36: / | F36: =M29 -> 19.878572 | G36: = | H36: =ROUNDUP(D36/F36,2) -> 34.59
H37: > 2.00 Hence OK

Sheet CROSS SECTION
A1: CROSS SECTION OF RIVER DOWN-STREAM
A2: ='Deck Anchorage'!A2 -> Name Of Work :- Construction of Submersible Bridge on ON KHERWARA - JAWAS - SUVERI ROAD IN KM 9/000, ACROSS RIVER SOM
A3: CROSS SECTION OF RIVER AT PROPOSED BRIDGE SITE
A4: HIGHEST FLOOD LEVEL | F4: =HYDRAULICS!F4 -> 100.6 | G4: M
A5: Chainage in M (u/s or d/s) | B5: RL in M | C5: DEPTH OF FLOW IN M | D5: LENGTH OF FLOW | E5: AVERAGE DEPTH OF FLOW | F5: CROSS SECTIONAL AREA OF FLOW | G5: WETTED PERIMETER
A6: 0 | B6: 102 | C6: =IF(B6>$F$4,0,$F$4-B6) -> 0 | D6: 0 | E6: 0 | F6: 0 | G6: 0
A7: 10 | B7: 100.95 | C7: =IF(B7>$F$4,0,$F$4-B7) -> 0 | D7: =(A7-A6) -> 10 | E7: =(C7+C6)/2 -> 0 | F7: =D7*E7 -> 0 | G7: =(D7^2+(C6-C7)^2)^0.5 -> 10
A8: 20 | B8: 98.19 | C8: =IF(B8>$F$4,0,$F$4-B8) -> 2.41 | D8: =(A8-A7) -> 10 | E8: =(C8+C7)/2 -> 1.205 | F8: =D8*E8 -> 12.05 | G8: =(D8^2+(C7-C8)^2)^0.5 -> 10.286306
A9: 30 | B9: 97.59 | C9: =IF(B9>$F$4,0,$F$4-B9) -> 3.01 | D9: =(A9-A8) -> 10 | E9: =(C9+C8)/2 -> 2.71 | F9: =D9*E9 -> 27.1 | G9: =(D9^2+(C8-C9)^2)^0.5 -> 10.017984
A10: 40 | B10: 97.21 | C10: =IF(B10>$F$4,0,$F$4-B10) -> 3.39 | D10: =(A10-A9) -> 10 | E10: =(C10+C9)/2 -> 3.2 | F10: =D10*E10 -> 32 | G10: =(D10^2+(C9-C10)^2)^0.5 -> 10.007217
A11: 50 | B11: 96.87 | C11: =IF(B11>$F$4,0,$F$4-B11) -> 3.73 | D11: =(A11-A10) -> 10 | E11: =(C11+C10)/2 -> 3.56 | F11: =D11*E11 -> 35.6 | G11: =(D11^2+(C10-C11)^2)^0.5 -> 10.005778
A12: 60 | B12: 97.96 | C12: =IF(B12>$F$4,0,$F$4-B12) -> 2.64 | D12: =(A12-A11) -> 10 | E12: =(C12+C11)/2 -> 3.185 | F12: =D12*E12 -> 31.85 | G12: =(D12^2+(C11-C12)^2)^0.5 -> 10.05923
A13: 70 | B13: 97.12 | C13: =IF(B13>$F$4,0,$F$4-B13) -> 3.48 | D13: =(A13-A12) -> 10 | E13: =(C13+C12)/2 -> 3.06 | F13: =D13*E13 -> 30.6 | G13: =(D13^2+(C12-C13)^2)^0.5 -> 10.035218
A14: 80 | B14: 96.8 | C14: =IF(B14>$F$4,0,$F$4-B14) -> 3.8 | D14: =(A14-A13) -> 10 | E14: =(C14+C13)/2 -> 3.64 | F14: =D14*E14 -> 36.4 | G14: =(D14^2+(C13-C14)^2)^0.5 -> 10.005119
A15: 90 | B15: 96.47 | C15: =IF(B15>$F$4,0,$F$4-B15) -> 4.13 | D15: =(A15-A14) -> 10 | E15: =(C15+C14)/2 -> 3.965 | F15: =D15*E15 -> 39.65 | G15: =(D15^2+(C14-C15)^2)^0.5 -> 10.005444
A16: 100 | B16: 96.49 | C16: =IF(B16>$F$4,0,$F$4-B16) -> 4.11 | D16: =(A16-A15) -> 10 | E16: =(C16+C15)/2 -> 4.12 | F16: =D16*E16 -> 41.2 | G16: =(D16^2+(C15-C16)^2)^0.5 -> 10.00002
A17: 110 | B17: 97.04 | C17: =IF(B17>$F$4,0,$F$4-B17) -> 3.56 | D17: =(A17-A16) -> 10 | E17: =(C17+C16)/2 -> 3.835 | F17: =D17*E17 -> 38.35 | G17: =(D17^2+(C16-C17)^2)^0.5 -> 10.015114
A18: 120 | B18: 97.29 | C18: =IF(B18>$F$4,0,$F$4-B18) -> 3.31 | D18: =(A18-A17) -> 10 | E18: =(C18+C17)/2 -> 3.435 | F18: =D18*E18 -> 34.35 | G18: =(D18^2+(C17-C18)^2)^0.5 -> 10.003125
... A25: 190 | B25: 102 | C25: =IF(B25>$F$4,0,$F$4-B25) -> 0 | D25: =(A25-A24) -> 10 | E25: =(C25+C24)/2 -> 0 | F25: =D25*E25 -> 0 | G25: =(D25^2+(C24-C25)^2)^0.5 -> 10
C27: TOTAL | D27: =SUM(D6:D26) -> 190 | F27: =SUM(F6:F26) -> 490.3 | G27: =SUM(G6:G26) -> 190.70731
A28: =A6 -> 0 | B28: =HYDRAULICS!F4 -> 100.6
A29: =A25 -> 190 | B29: =B28 -> 100.6

Sheet Bed Slope
A1: DETERMINATION OF BED SLOPE OF THE RIVER
A2: ='CROSS SECTION'!A2:J2 -> Name Of Work :- Construction of Submersible Bridge on ON KHERWARA - JAWAS - SUVERI ROAD IN KM 9/000, ACROSS RIVER SOM
A3: Chainage in M (u/s or d/s) | B3: RL in M
A4: 0 | B4: 94.505
A5: 25 | B5: =B4-0.025 -> 94.48
A6: =A5+25 -> 50 | B6: =B5-0.025 -> 94.455
A7: =A6+25 -> 75 | B7: =B6-0.025 -> 94.43
A8: =A7+25 -> 100 | B8: =B7-0.025 -> 94.405
A9: =A8+25 -> 125 | B9: 94.37
A10: =A9+25 -> 150 | B10: 94.36
A11: =A10+25 -> 175 | B11: =B10-0.025 -> 94.335
A12: =A11+25 -> 200 | B12: =B11-0.025 -> 94.31
A13: =A12+25 -> 225 | B13: =B12-0.025 -> 94.285
A14: 235 | B14: =B13-0.025 -> 94.26
D17: Reference Poits
D18: Ch | E18: RL
D19: =A4 -> 0 | E19: =B4 -> 94.505
D20: =A14 -> 235 | E20: =B14 -> 94.26
G22: DISTANCE | I22: =D20-D19 -> 235 | J22: M
G23: FALL | I23: =E19-E20 -> 0.245 | J23: M
G24: SLOPE | H24: 1 | I24: IN | J24: =ROUNDUP(I22/I23,0) -> 960

Sheet SBC
A70: SBC RECOMMENDATION AT 3 M DEPTH IN THE WEATHERED ROCK IS 21.5, 22.45, 21.5 TONNE PER SQUARE METER;
A71: SBC RECOMMENDATION AT 3 M DEPTH IN THE WEATHERED ROCK IS 21.5, 22.45, 21.5 TONNE PER SQUARE METER;
A73: HOWEVER ADOPTED SBC IS
D74: 20 | E74: TONNE PER SQUARE METER
C76: OR | D76: =D74*10 -> 200 | E76: KN PER SQUARE METER
D78: Hard Rock | F78: no

Sheet STABILITY CHECK FOR PIER
A1: DESIGN OF PIER AND CHECK FOR STABILITY- SUBMERSIBLE BRIDGE
A2: ='abstract of stresses'!A2:N2 -> Name Of Work :- Construction of Submersible Bridge on ON KHERWARA - JAWAS - SUVERI ROAD IN KM 9/000, ACROSS RIVER SOM
A3: DESIGN DATA
A5: 1 | B5: RIGHT EFFECTIVE SPAN | D5: = | E5: 7.6 | F5: M | G5: Degree of Skew | K5: Degrees
A6: =A5+1 -> 2 | B6: SPAN C/C OF PIERS | D6: = | E6: =E5+1.2 -> 8.8 | F6: M
A7: =A6+1 -> 3 | B7: OVERALL WIDTH OF PIER CAP | D7: = | E7: 8.4 | F7: M | H7: COS Theta
A8: =A7+1 -> 4 | B8: H.F.L. | D8: = | E8: =HYDRAULICS!F4 -> 100.6 | F8: M
A9: =A8+1 -> 5 | B9: BUOYANCY
A10: =A9+1 -> 6 | C10: AT FOOTING LEVEL | D10: = | E10: 100 | F10: %
A11: =A10+1 -> 7 | C11: AT PIER LEVEL | D11: = | E11: 100 | F11: %
A12: =A11+1 -> 8 | B12: AQUEDUCT FALLS UNDER ZONE-II SO SEISMIC CASE IS NOT GOVERNING HERE.
A13: =A12+1 -> 9 | B13: FLOOD DISCHARGE | D13: = | E13: =HYDRAULICS!C35 -> 899.92993 | F13: CUMECS
A14: =A13+1 -> 10 | B14: RIVER BED SLOPE | D14: = | E14: 1 | F14: IN | G14: =HYDRAULICS!C33 -> 960
A15: =A14+1 -> 11 | B15: DESIGN VELOCITY | D15: = | E15: =HYDRAULICS!C34 -> 1.8354679 | F15: m/sec
A16: =A15+1 -> 12 | B16: BED LEVEL OF THE HEIGHEST PIER | D16: = | E16: =HYDRAULICS!E43 -> 96.47 | F16: M
A17: =A16+1 -> 13 | B17: SAFE BEARING CAPACITY | D17: = | E17: 20 | F17: t/m2 | G17: =E17*10 -> 200 | H17: kN/m2
A18: =A17+1 -> 14 | B18: TOP LEVEL OF FOUNDING ROCK | D18: = | E18: =HYDRAULICS!E45 -> 93.47 | F18: M
A19: =A18+1 -> 15 | B19: EMBEDMENT OF PIER IN HARD ROCK | D19: = | E19: 1.5 | F19: M | G19: Weathered Rock
A20: =A19+1 -> 16 | B20: FOUNDATION LEVEL OF THE HIGHEST PIER | D20: = | E20: =E18-E19 -> 91.97 | F20: M
A21: =A20+1 -> 17 | B21: DECK LEVEL OF THE BRIDGE | D21: = | E21: ='afflux calculation'!B50 -> 101.6 | F21: M
A22: =A21+1 -> 18 | B22: TOP LEVEL OF THE PIER CAP | D22: = | E22: =E21-H27-H28 -> 100.775 | F22: M
A23: =A22+1 -> 19 | B23: LEVEL DIFFERENCE OF PIER CAP TOP AND FOUNDING LEVEL | D23: = | E23: =E22-E20 -> 8.805 | F23: M
A24: =CONCATENATE("CHECKING STABILITY OF PIER AT R.L.",E20," ",F20, " FOOTING LEVEL") -> CHECKING STABILITY OF PIER AT R.L.91.97 M FOOTING LEVEL
A25: A | B25: DEAD LOAD CALCULATION
B26: SUPER STRUCTURE | H26: SLAB 775 TO 925 MM
B27: Self Weight of Slab | C27: = | D27: =E6 -> 8.8 | E27: x | F27: 8.4 | G27: x | H27: 0.75 | I27: x | J27: 24 | K27: = | L27: =D27*F27*H27*J27 -> 1330.56 | M27: kN
B28: Self Weight of Wearing Coat | C28: = | D28: =D27 -> 8.8 | E28: x | F28: 8.4 | G28: x | H28: 0.075 | I28: x | J28: 24 | K28: = | L28: =D28*F28*H28*J28 -> 133.056 | M28: kN
B29: TOTAL | L29: =SUM(L27:L28) -> 1463.616 | M29: kN
B30: SUB STRUCTURE
B31: Pier Cap
B32: Pier Cap | C32: = | D32: 1.5 | E32: x | F32: 8.4 | G32: x | H32: 0.6 | I32: x | J32: 24 | O32: = | P32: =J32*H32*F32*D32 -> 181.44 | Q32: kN
B33: Flared Portion Sides | C33: = | D33: 0.5 | E33: x | F33: 0.15 | G33: x | H33: 0.6 | I33: x | J33: =F32 -> 8.4 | K33: x | L33: 2 | M33: x | N33: 24 | O33: = | P33: =D33*F33*H33*J33*L33*N33 -> 18.144 | Q33: kN
C34: = | D34: 0.5 | E34: x | F34: =F33 -> 0.15 | G34: x | H34: 0.6 | I34: x | J34: 3.14 | K34: x | L34: 1.2 | M34: x | N34: 24 | O34: = | P34: =D34*F34*H34*J34*L34*N34 -> 4.06944 | Q34: kN
B35: Flared Portion u/s & d/s Sides | C35: = | D35: 0.6 | E35: x | F35: 0.6 | G35: x | H35: 1.5 | I35: x | J35: 24 | O35: = | P35: =J35*H35*F35*D35 -> 12.96 | Q35: kN
C36: = | D36: 3.14 | E36: / | F36: 4 | G36: x | H36: 1.2 | I36: x | J36: 1.2 | K36: x | L36: 0.6 | M36: x | N36: 24 | O36: = | P36: =D36/F36*H36*J36*L36*N36 -> 16.27776 | Q36: kN
B37: TOTAL | P37: =SUM(P32:P36) -> 232.8912 | Q37: kN
B38: Pier
B39: Flared Portion Top | C39: = | D39: 0.5 | E39: x | F39: =F33 -> 0.15 | G39: x | H39: 0.6 | I39: x | J39: =F32 -> 8.4 | K39: x | L39: 2 | M39: x | N39: 24 | O39: = | P39: =D39*F39*H39*J39*L39*N39 -> 18.144 | Q39: kN
C40: = | D40: 0.5 | E40: x | F40: =F34 -> 0.15 | G40: x | H40: 0.6 | I40: x | J40: 3.14 | K40: x | L40: =L34 -> 1.2 | M40: x | N40: 24 | O40: = | P40: =D40*F40*H40*J40*L40*N40 -> 4.06944 | Q40: kN
B41: Pier Rectangular portion | C41: = | D41: 1.2 | E41: x | F41: 7.5 | G41: x | H41: =E23-1.2-0.6-1.05 -> 5.955 | I41: x | J41: 24 | O41: = | P41: =J41*H41*F41*D41 -> 1286.28 | Q41: kN
...

Sheet abstract of stresses
A1: ABSTRACT OF BASE PRESSURE AND STRESSES
A2: ='afflux calculation'!A2:H2 -> Name Of Work :- Construction of Submersible Bridge on ON KHERWARA - JAWAS - SUVERI ROAD IN KM 9/000, ACROSS RIVER SOM
A3: ='STABILITY CHECK FOR PIER'!B198 -> CASE- 1 FOR SERVICE CONDITION AT R. L.91.97 M | I3: ='STABILITY CHECK FOR PIER'!D216 -> 137.44144 | J3: ='STABILITY CHECK FOR PIER'!D219 -> 60.96724 | K3: ='STABILITY CHECK FOR PIER'!D225 -> 137.48902 | L3: ='STABILITY CHECK FOR PIER'!D228 -> 73.014819
A4: ='STABILITY CHECK FOR PIER'!B231 -> CASE- 2 FOR IDLE CONDITION AT R. L.91.97 M | I4: ='STABILITY CHECK FOR PIER'!D242 -> 87.049549 | J4: ='STABILITY CHECK FOR PIER'!D245 -> 76.786042 | K4: ='STABILITY CHECK FOR PIER'!D251 -> 99.097128 | L4: ='STABILITY CHECK FOR PIER'!D254 -> 88.833621
A5: ='STABILITY CHECK FOR PIER'!B257 -> CASE- 3 FOR WIND FORCE AT SERVICE CONDITION AT R. L.91.97 M | I5: ='STABILITY CHECK FOR PIER'!$D270 -> 138.61352 | J5: ='STABILITY CHECK FOR PIER'!$D273 -> 59.795159 | K5: ='STABILITY CHECK FOR PIER'!$D279 -> 138.6611 | L5: ='STABILITY CHECK FOR PIER'!$D282 -> 71.842739
A6: ='STABILITY CHECK FOR PIER'!B285 -> CASE- 4 FOR WIND FORCE AT IDLE CONDITION AT R. L.91.97 M | I6: ='STABILITY CHECK FOR PIER'!$D298 -> 88.221629 | J6: ='STABILITY CHECK FOR PIER'!$D301 -> 75.613961 | K6: ='STABILITY CHECK FOR PIER'!$D304 -> 83.40903 | L6: ='STABILITY CHECK FOR PIER'!$D307 -> 80.426561 | M6: ='STABILITY CHECK FOR PIER'!$D312 -> 100.26921 | N6: ='STABILITY CHECK FOR PIER'!$D315 -> 87.661541
A7: ='STABILITY CHECK FOR PIER'!B319 -> CASE- 5 FOR ONE SPAN DISLODGED CONDITION AT R. L.91.97 M | I7: ='STABILITY CHECK FOR PIER'!$D332 -> 72.173208 | J7: ='STABILITY CHECK FOR PIER'!$D335 -> 59.56554 | K7: ='STABILITY CHECK FOR PIER'!$D337 -> 67.360609 | L7: ='STABILITY CHECK FOR PIER'!$D340 -> 64.37814 | M7: ='STABILITY CHECK FOR PIER'!$D345 -> 77.916954 | N7: ='STABILITY CHECK FOR PIER'!$D349 -> 74.01942
C9: Maximum | D9: =MAX(I3:N7) -> 138.6611 | F9: =MIN(I3:N7) -> 59.56554 | G9: Minimum
A11: ='STABILITY CHECK FOR PIER'!B356 -> CASE- 6 FOR SERVICE CONDITION AT R. L.92.97 M | I11: ='STABILITY CHECK FOR PIER'!$D374 -> 463.22984 | J11: ='STABILITY CHECK FOR PIER'!$D377 -> 76.397639 | K11: ='STABILITY CHECK FOR PIER'!$D383 -> 469.71384 | L11: ='STABILITY CHECK FOR PIER'!$D386 -> 82.881641
A12: ='STABILITY CHECK FOR PIER'!B388 -> CASE- 7 FOR IDLE CONDITION AT R. L.92.97 M | I12: ='STABILITY CHECK FOR PIER'!$D399 -> 245.62751 | J12: ='STABILITY CHECK FOR PIER'!$D402 -> 184.51853 | K12: ='STABILITY CHECK FOR PIER'!$D408 -> 252.11151 | L12: ='STABILITY CHECK FOR PIER'!$D411 -> 191.00253
A13: ='STABILITY CHECK FOR PIER'!B414 -> CASE- 8 FOR WIND FORCE AT SERVICE CONDITION AT R. L.92.97 M | I13: ='STABILITY CHECK FOR PIER'!$D427 -> 466.74006 | J13: ='STABILITY CHECK FOR PIER'!$D430 -> 72.88742 | K13: ='STABILITY CHECK FOR PIER'!$D436 -> 473.22406 | L13: ='STABILITY CHECK FOR PIER'!$D439 -> 79.371421
A14: ='STABILITY CHECK FOR PIER'!B442 -> CASE- 9 FOR WIND FORCE AT IDLE CONDITION AT R. L.92.97 M | I14: ='STABILITY CHECK FOR PIER'!$D455 -> 303.87845 | J14: ='STABILITY CHECK FOR PIER'!$D458 -> 235.74903 | K14: ='STABILITY CHECK FOR PIER'!$D464 -> 310.36245 | L14: ='STABILITY CHECK FOR PIER'!$D467 -> 242.23303
C16: Maximum | D16: =MAX(I11:N14) -> 473.22406 | F16: =MIN(I11:N14) -> 72.88742 | G16: Minimum

Sheet STEEL IN FLARED  PIER BASE 
A1: REINFORCEMENT CALCULATION IN PIER IN LOWER FLARED PORTION
A2: ='STABILITY CHECK FOR PIER'!A2:Q2 -> Name Of Work :- Construction of Submersible Bridge on ON KHERWARA - JAWAS - SUVERI ROAD IN KM 9/000, ACROSS RIVER SOM
B3: R.L. | C3: ='STABILITY CHECK FOR PIER'!E20+'STABILITY CHECK FOR PIER'!J52 -> 92.97 | D3: M TO | E3: =C3+0.6 -> 93.57 | F3: M
A4: FOR SERVICE CONDITION
B5: VERTICAL LOADS
B6: ='STABILITY CHECK FOR PIER'!B201 -> SUPER STRUCTURE | C6: ='STABILITY CHECK FOR PIER'!C201 -> = | D6: ='STABILITY CHECK FOR PIER'!D359 -> 1463.616 | E6: ='STABILITY CHECK FOR PIER'!E201 -> kN
B7: ='STABILITY CHECK FOR PIER'!B202 -> SUB STRUCTURE | C7: ='STABILITY CHECK FOR PIER'!C202 -> = | D7: ='STABILITY CHECK FOR PIER'!D360 -> 1726.8051 | E7: ='STABILITY CHECK FOR PIER'!E202 -> kN | F7: ='STABILITY CHECK FOR PIER'!F202 -> Without Buoyancy
B8: ='STABILITY CHECK FOR PIER'!B203 -> SUB STRUCTURE | C8: ='STABILITY CHECK FOR PIER'!C203 -> = | D8: ='STABILITY CHECK FOR PIER'!D361 -> 1633.4355 | E8: ='STABILITY CHECK FOR PIER'!E203 -> kN | F8: ='STABILITY CHECK FOR PIER'!F203 -> With Buoyancy
B9: ='STABILITY CHECK FOR PIER'!B204 -> LIVE LOAD | C9: ='STABILITY CHECK FOR PIER'!C204 -> = | D9: ='STABILITY CHECK FOR PIER'!D362 -> 788.26635 | E9: ='STABILITY CHECK FOR PIER'!E204 -> kN
B10: ='STABILITY CHECK FOR PIER'!B205 -> Total Load without Buoyancy | C10: ='STABILITY CHECK FOR PIER'!C205 -> = | D10: ='STABILITY CHECK FOR PIER'!D363 -> 3978.6874 | E10: ='STABILITY CHECK FOR PIER'!E205 -> kN
B11: ='STABILITY CHECK FOR PIER'!B206 -> Total Load with Buoyancy | C11: ='STABILITY CHECK FOR PIER'!C206 -> = | D11: ='STABILITY CHECK FOR PIER'!D364 -> 3885.3178 | E11: ='STABILITY CHECK FOR PIER'!E206 -> kN
B12: ='STABILITY CHECK FOR PIER'!B422 -> Total LONGITUDINAL MOMENT
B13: Moment @ R. L. | C13: =C15 -> 92.97 | D13: =D15 -> M = | E13: ='STABILITY CHECK FOR PIER'!$J$422 -> 324.25052 | F13: ='STABILITY CHECK FOR PIER'!K115 -> kN-m
B14: ='STABILITY CHECK FOR PIER'!B423 -> Total TRANSVERSE MOMENT
B15: Moment @ R. L. | C15: ='STABILITY CHECK FOR PIER'!D155 -> 92.97 | D15: ='STABILITY CHECK FOR PIER'!E155 -> M = | E15: ='STABILITY CHECK FOR PIER'!$J$423 -> 2428.9727 | F15: ='STABILITY CHECK FOR PIER'!K156 -> kN-m
B16: =[1]TROUGH!A21 -> CONCRETE MIX | D16: M-25
B17: =[1]TROUGH!A22 -> CHARACTERISTIC STRENGTH OF REINFORCEMENT | F17: =[1]TROUGH!F22 -> 415 | G17: =[1]TROUGH!G22 -> N/mm2
B18: =[1]TROUGH!A23 -> PERMISSIBLE STRESSES
B19: =[1]TROUGH!B24 -> IN STEEL | D19: 190
B20: =[1]TROUGH!B31 -> IN CONCRETE
B21: CHARACTERISTIC STRENGTH OF Concrete | D21: fck | E21: = | F21: 30 | G21: N/mm2
B22: =[1]TROUGH!B32 -> Permissible Compressive Stress in Bending | D22: =[1]TROUGH!C32 -> σcbc | E22: =[1]TROUGH!D32 -> = | F22: 8 | G22: =[1]TROUGH!F32 -> N/mm2
B23: =[1]TROUGH!B33 -> Permissible Compressive Stress in Direct Compression | D23: =[1]TROUGH!C33 -> σcc | E23: =[1]TROUGH!D33 -> = | F23: =[1]TROUGH!E33 -> 8 | G23: =[1]TROUGH!F33 -> N/mm2
D24: =[1]TROUGH!C34 -> σct | E24: =[1]TROUGH!D34 -> = | F24: =[1]TROUGH!E34 -> 3.6 | G24: =[1]TROUGH!F34 -> N/mm2
B25: Ultimate Axial Load PU | C25: = | D25: 1.5 | E25: X | F25: =D10 -> 3978.6874 | G25: = | H25: =D25*F25 -> 5968.0312 | I25: kN
B26: Ultimate Longitudinal Moment MU | C26: = | D26: 1.5 | E26: X | F26: =E13 -> 324.25052 | G26: = | H26: =D26*F26 -> 486.37578 | I26: kN-m
B27: Ultimate Transverse Moment MU | C27: = | D27: 1.5 | E27: X | F27: =E15 -> 2428.9727 | G27: = | H27: =D27*F27 -> 3643.4591 | I27: kN-m
B28: INCREASE WHEN WIND CONDITION IS CONSIDERED | F28: 33.33 | G28: %
B29: Neglecting area of Cut and Ease water parts Rectangular Section considered is
C30: ='STEEL IN PIER'!C30+(2*'STABILITY CHECK FOR PIER'!M63) -> 12001.2 | D30: mm x | E30: ='STEEL IN PIER'!E30++(2*'STABILITY CHECK FOR PIER'!M63) -> 1201.2 | F30: mm
C31: Assume cover as | D31: 75
B32: d1/d | C32: = | D32: =D31+C51/2 -> 87.5 | E32: / | F32: =E30 -> 1201.2 | G32: = | H32: =D32/F32 -> 0.072843823
B33: PU/(fck b d) | C33: = | D33: =H25 -> 5968.0312 | E33: x | F33: 1000 | G33: / ( | H33: =$F$21 -> 30 | I33: x | J33: =$C$30 -> 12001.2 | K33: x | L33: =$E$30 -> 1201.2 | M33: )
C34: = | D34: =D33*F33/(H33*J33*L33) -> 0.013799706
B35: FOR LONGITUDINAL MOMENT
B36: Mu/(fck b d2) | C36: = | D36: =H26 -> 486.37578 | E36: =E33 -> x | F36: =$F$33*1000 -> 1000000 | G36: / ( | H36: =$F$21 -> 30 | I36: x | J36: =$C$30 -> 12001.2 | K36: x | L36: =$E$30 -> 1201.2 | M36: 2 )
C37: = | D37: =D36*F36/(H36*J36*L36^2) -> 0.00093625763
B38: Refer Chart 31 & 32 of Design Aids for Reinforced concrete SP-16 the point lies below the range of applicability. Hence provide minimum percentage of steel.
B39: The point lies below the range of applicability. Hence provide minimum percentage of steel
B40: CRITERIA 1 FOR MINIMUM STEEL Pt = 0.8 % OF CROSS SECTION AREA OF COLUMN REQUIRED FOR COMPRESSION
...

Sheet STEEL IN PIER
A1: REINFORCEMENT CALCULATION IN PIER
A2: ='STEEL IN FLARED PIER BASE '!A2:O2 -> Name Of Work :- Construction of Submersible Bridge on ON KHERWARA - JAWAS - SUVERI ROAD IN KM 9/000, ACROSS RIVER SOM
B3: R.L. | C3: ='STEEL IN FLARED PIER BASE '!E3 -> 93.57 | D3: M TO | E3: =102-1.2 -> 100.8 | F3: M
A4: FOR SERVICE CONDITION
B5: VERTICAL LOADS
B6: ='STABILITY CHECK FOR PIER'!B201 -> SUPER STRUCTURE | C6: ='STABILITY CHECK FOR PIER'!C201 -> = | D6: ='STABILITY CHECK FOR PIER'!D201 -> 1463.616 | E6: ='STABILITY CHECK FOR PIER'!E201 -> kN
B7: ='STABILITY CHECK FOR PIER'!B202 -> SUB STRUCTURE | C7: ='STABILITY CHECK FOR PIER'!C202 -> = | D7: ='STABILITY CHECK FOR PIER'!D202 -> 2821.2051 | E7: ='STABILITY CHECK FOR PIER'!E202 -> kN | F7: ='STABILITY CHECK FOR PIER'!F202 -> Without Buoyancy
B8: ='STABILITY CHECK FOR PIER'!B203 -> SUB STRUCTURE | C8: ='STABILITY CHECK FOR PIER'!C203 -> = | D8: ='STABILITY CHECK FOR PIER'!D203 -> 2271.8355 | E8: ='STABILITY CHECK FOR PIER'!E203 -> kN | F8: ='STABILITY CHECK FOR PIER'!F203 -> With Buoyancy
B9: ='STABILITY CHECK FOR PIER'!B204 -> LIVE LOAD | C9: ='STABILITY CHECK FOR PIER'!C204 -> = | D9: ='STABILITY CHECK FOR PIER'!D204 -> 788.26635 | E9: ='STABILITY CHECK FOR PIER'!E204 -> kN
B10: ='STABILITY CHECK FOR PIER'!B205 -> Total Load without Buoyancy | C10: ='STABILITY CHECK FOR PIER'!C205 -> = | D10: ='STABILITY CHECK FOR PIER'!D205 -> 5073.0874 | E10: ='STABILITY CHECK FOR PIER'!E205 -> kN
B11: ='STABILITY CHECK FOR PIER'!B206 -> Total Load with Buoyancy | C11: ='STABILITY CHECK FOR PIER'!C206 -> = | D11: ='STABILITY CHECK FOR PIER'!D206 -> 4523.7178 | E11: ='STABILITY CHECK FOR PIER'!E206 -> kN
B12: ='STABILITY CHECK FOR PIER'!B422 -> Total LONGITUDINAL MOMENT
B13: Moment @ R. L. | C13: =C3 -> 93.57 | D13: =D15 -> M = | E13: ='STABILITY CHECK FOR PIER'!H207 -> 356.8141 | F13: ='STABILITY CHECK FOR PIER'!K115 -> kN-m
B14: ='STABILITY CHECK FOR PIER'!B423 -> Total TRANSVERSE MOMENT
B15: Moment @ R. L. | C15: =C3 -> 93.57 | D15: ='STABILITY CHECK FOR PIER'!E155 -> M = | E15: ='STABILITY CHECK FOR PIER'!H208 -> 2360.442 | F15: ='STABILITY CHECK FOR PIER'!K156 -> kN-m
B16: =[1]TROUGH!A21 -> CONCRETE MIX | D16: ='STEEL IN FLARED PIER BASE '!D16 -> M-25
B17: =[1]TROUGH!A22 -> CHARACTERISTIC STRENGTH OF REINFORCEMENT | F17: =[1]TROUGH!F22 -> 415 | G17: =[1]TROUGH!G22 -> N/mm2
B18: =[1]TROUGH!A23 -> PERMISSIBLE STRESSES
B19: =[1]TROUGH!B24 -> IN STEEL | D19: 190
B20: =[1]TROUGH!B31 -> IN CONCRETE
B21: CHARACTERISTIC STRENGTH OF Concrete | D21: fck | E21: = | F21: 30 | G21: N/mm2
B22: =[1]TROUGH!B32 -> Permissible Compressive Stress in Bending | D22: =[1]TROUGH!C32 -> σcbc | E22: =[1]TROUGH!D32 -> = | F22: 8 | G22: =[1]TROUGH!F32 -> N/mm2
B23: =[1]TROUGH!B33 -> Permissible Compressive Stress in Direct Compression | D23: =[1]TROUGH!C33 -> σcc | E23: =[1]TROUGH!D33 -> = | F23: =[1]TROUGH!E33 -> 8 | G23: =[1]TROUGH!F33 -> N/mm2
D24: =[1]TROUGH!C34 -> σct | E24: =[1]TROUGH!D34 -> = | F24: =[1]TROUGH!E34 -> 3.6 | G24: =[1]TROUGH!F34 -> N/mm2
B25: Ultimate Axial Load PU | C25: = | D25: 1.5 | E25: X | F25: =D10 -> 5073.0874 | G25: = | H25: =D25*F25 -> 7609.6312 | I25: kN
B26: Ultimate Longitudinal Moment MU | C26: = | D26: 1.5 | E26: X | F26: =E13 -> 356.8141 | G26: = | H26: =D26*F26 -> 535.22115 | I26: kN-m
B27: Ultimate Transverse Moment MU | C27: = | D27: 1.5 | E27: X | F27: =E15 -> 2360.442 | G27: = | H27: =D27*F27 -> 3540.663 | I27: kN-m
B28: INCREASE WHEN WIND CONDITION IS CONSIDERED | F28: 33.33 | G28: %
B29: Neglecting area of Cut and Ease water parts Rectangular Section considered is
C30: 12000 | D30: mm x | E30: 1200 | F30: mm
C31: Assume cover as | D31: 75
B32: d1/d | C32: = | D32: =D31+C51/2 -> 87.5 | E32: / | F32: =E30 -> 1200 | G32: = | H32: =D32/F32 -> 0.072916667
B33: PU/(fck b d) | C33: = | D33: =H25 -> 7609.6312 | E33: x | F33: 1000 | G33: / ( | H33: =$F$21 -> 30 | I33: x | J33: =$C$30 -> 12000 | K33: x | L33: =$E$30 -> 1200 | M33: )
C34: = | D34: =D33*F33/(H33*J33*L33) -> 0.017614887
B35: FOR LONGITUDINAL MOMENT
B36: Mu/(fck b d2) | C36: = | D36: =H26 -> 535.22115 | E36: =E33 -> x | F36: =$F$33*1000 -> 1000000 | G36: / ( | H36: =$F$21 -> 30 | I36: x | J36: =$C$30 -> 12000 | K36: x | L36: =$E$30 -> 1200 | M36: 2 )
C37: = | D37: =D36*F36/(H36*J36*L36^2) -> 0.0010324482
B38: Refer Chart 31 & 32 of Design Aids for Reinforced concrete SP-16 the point lies below the range of applicability. Hence provide minimum percentage of steel.
B39: The point lies below the range of applicability. Hence provide minimum percentage of steel
B40: CRITERIA 1 FOR MINIMUM STEEL Pt = 0.8 % OF CROSS SECTION AREA OF COLUMN REQUIRED FOR COMPRESSION
...

Sheet FOOTING DESIGN
A1: DESIGN OF PIER FOOTING SUBMERSIBLE BRIDGE
A2: ='STEEL IN PIER'!A2:O2 -> Name Of Work :- Construction of Submersible Bridge on ON KHERWARA - JAWAS - SUVERI ROAD IN KM 9/000, ACROSS RIVER SOM
A3: FOR WIND AT SERVICE CONDITION
B4: Length of footing | C4: lf | D4: ='STABILITY CHECK FOR PIER'!E52 -> 12 | E4: m
B5: Width of Footing | C5: lb | D5: ='STABILITY CHECK FOR PIER'!G52 -> 3.8 | E5: m
B6: Width of Pier | D6: 1.2 | E6: m
B7: Vertical Load | C7: P | D7: ='STABILITY CHECK FOR PIER'!D263 -> 5073.0874 | E7: kN
B8: Longitudinal Moment | C8: Me | D8: ='STABILITY CHECK FOR PIER'!J265 -> 356.8141 | E8: kN-m
B9: Transverse Moment | C9: Mb | D9: ='STABILITY CHECK FOR PIER'!J266 -> 2467.3357 | E9: kN-m
B10: el | C10: = Me/P | D10: =D8/D7 -> 0.070334704 | E10: m
B11: eb | C11: = Mb/P | D11: =D9/D7 -> 0.48635782 | E11: m
B12: el/lf | D12: =D10/D4 -> 0.0058612253 | E12: Refer VK Raina "Concrete Bridge Practice : Analysis, Design and Economics " Chapter 14 "Evaluation of Base Presssure and Contact Area" Fig 14.2 & 14.3
B13: eb/lb | D13: =D11/D5 -> 0.1279889
B14: K | D14: 1
B15: y | D15: 0
B16: Area in Tension = y x lb | E16: =D5*D15 -> 0 | F16: m2 | G16: =E16/D5*100 -> 0 | H16: %
B17: Maximum Pressure before Redistribution | E17: ='STABILITY CHECK FOR PIER'!D279 -> 138.6611 | F17: kN/m2
B18: Maximum Pressure After Redistribution = pxK | E18: =E17*D14 -> 138.6611 | F18: kN/m2
B19: Maximum Stress at Edge of Pier | E19: =E18 -> 138.6611 | F19: kN/m2
B20: Distance From Face of Pier to the Edge | E20: ='Footing STRESS DIAGRAM'!C4 -> 1.3 | F20: m
B21: Stress at the Edge of Pier | E21: =(D5-E16-E20)*E19/(D5-E16) -> 91.224405 | F21: kN/m2
B22: Average Stress on Cantilevered Area | E22: =(E19+E21)/2 -> 114.94275 | F22: kN/m2
B23: Area of the Cantilever Portion | E23: =E20*1 -> 1.3 | F23: m2
B24: Distance of Centroid of the Stress in Cantilever Portion | E24: =E20/3*(E21+2*E19)/(E19+E21) -> 0.69470899 | F24: m
B25: Moment about the Face of Pier | E25: =E22*E23*E24 -> 103.80729 | F25: kN-m
B26: CONCRETE GRADE | E26: ='STEEL IN PIER'!D16 -> M-25
B27: FOR THIS GRADE scbc | E27: 10 | F27: N/mm2
B28: m | E28: =280/(3*E27) -> 9.3333333
B29: sst | E29: 200
B30: factor k | E30: =(E28*E27)/(E27*E28+E29) -> 0.31818182
B31: j | E31: =1-(E30/3) -> 0.89393939
B32: R | E32: =0.5*E27*E31*E30 -> 1.4221763
B33: Effective Depth Required | E33: =SQRT((E25*1000*1000)/(E32*1000)) -> 270.17005 | F33: mm
B34: Adopt Total Depth | E34: ='STABILITY CHECK FOR PIER'!J52*1000 -> 1000 | F34: mm
B35: Cover | E35: 50 | F35: mm
B36: Assume Bar Dia | E36: 25 | F36: mm
B37: Keeping A Cover Of 50 mm Effective Depth | E37: =E34-E35-E36/2 -> 937.5 | F37: mm
B38: Adopt Effective Depth | E38: =IF(E33>E37,E33,E37) -> 937.5 | F38: mm
B39: Steel Required Ast | E39: =(E25*1000*1000)/(E29*E31*E38) -> 619.32486 | F39: mm2
B40: Area Of One Bar | E40: =3.14*E36*E36/4 -> 490.625 | F40: mm2
...

Sheet Footing STRESS DIAGRAM
D1: ='FOOTING DESIGN'!D6 -> 1.2 | E1: m
C4: =(D18-D1)/2 -> 1.3 | D4: m
D18: ='FOOTING DESIGN'!D5 -> 3.8 | E18: m
B21: ='FOOTING DESIGN'!E16 -> 0 | C21: m
E25: ='FOOTING DESIGN'!E21 -> 91.224405
E26: kN/m2 | G26: ='FOOTING DESIGN'!E19 -> 138.6611 | H26: kN/m2
D29: STRESS DIAGRAM
A31: DESIGN OF PIER FOOTING

Sheet Pier Cap LL tracked vehicle
A1: LIVE LOAD CALCULATION :-
A3: [1] CLASS AA TRACKED VEHICLE :-
A5: (a) Dispersion width along the span
A7: According to clause 305.13 IRC- 21-2000
A9: = Length of Contact + 2 (Wearing coat + depth of Slab)
A11: = | B11: 3.6 | C11: + 2 ( 0.075 + 0.775 )
A13: = | B13: 5.3 | C13: M
A14: (b) Dispersion width across the span
A16: According to clause 305.13 IRC- 21-2000
A18: be = K x ( 1 - x/Le ) +bw
A19: K = A Constant having the value depending upon the ratio
A20: (L1/Le where.
A21: be = the effective width of the slab on which the load acts.
A22: Le = Effective Span
A23: x = the distance of c.g. of concentrate load from the near support
A24: bw = The breadth of concentration area of the load i.e. Dimension of
A25: the tyre or track contact area over the road surface
A26: Heve ,
B27: Le = 10.00 M & L1 = 7.00 M
A29: = L1 | B29: = | C29: 7 | D29: = | E29: 0.7
A30: Le | C30: 10
A31: Value of K = | C31: 2.4
A33: bw = | B33: 0.85 + 2 x 0.075 | D33: = 1.0 M
A35: X = L | B35: = | C35: 10 | D35: = | E35: 5.0 M
A36: 2 | C36: 2
A37: be = 2.4 x 4 | C37: ( 1 - 5/10) | D37: + | E37: 1
A38: = | B38: =2.4*4*0.5+1 -> 5.8 | C38: M
A39: Impact factor is 13.75% as pere IRC Section-II, Clause - 211-3 (a) (i)
A41: DISPERSION ACROSS SPAN (CLASS AA TRACKED VEHICAL)
A42: The tracked vehicle is placed at a distance of minimum clearence of 1-2 m from Kerb
A43: Dispersion across span
A44: = C/C distance between wheels
A45: + width from centre of wheel on clearence side
A46: + Least on other side or halp the dispersion of one wheel.
A47: = 2.05 + 1.93 + Least of 2.715 OR 5.8/2
A48: = 2.05 + 1.93 + 2.715
A49: = 6.695
A50: Impact factor = 1.1375
A51: Total load with impact
... A54: = Intensity of Load
...

Sheet Pier Cap
A1: DESIGN OF PIER CAP :-
A2: D.L./ M Width along bridge
A3: DL. Of Slab = | C3: ='[6]STABILITY CHECK FOR PIER'!H27 -> 0.75 | D3: x | E3: ='[6]STABILITY CHECK ABUTMENT'!F4 -> 8.4 | F3: x. | G3: 2.4 | H3: = | I3: =C3*E3*G3 -> 15.12 | J3: T
A4: D.L. of Wearing coat = | C4: ='[6]STABILITY CHECK FOR PIER'!H28 -> 0.075 | D4: x | E4: =E3 -> 8.4 | F4: x. | G4: 2.4 | H4: = | I4: =C4*E4*G4 -> 1.512 | J4: T
G5: TOTAL | I5: =SUM(I3:I4) -> 16.632 | J5: T
A6: D.L. of Slab & Wearing coat on half of the pier | E6: =
E7: =I5 -> 16.632 | F7: / | G7: 2 | H7: = | I7: =E7/G7 -> 8.316 | J7: T
A8: L.L. on Pier cap including impact along bridge
D9: = | E9: 82.5 | F9: x | G9: 1.1375 | H9: = | I9: =E9*G9 -> 93.84375 | J9: T
A10: (Refer Live Load Computation)
A11: Dispersion width across the span for
A12: 70 T TRACKED VEHTCLE | D12: = | E12: 6.695 | F12: M
A13: ( Refer Solid slab design page SS-16)
A14: Live Load u.d.l. on Pier | D14: = | E14: =I9 -> 93.84375 | F14: / | G14: =E12 -> 6.695 | H14: = | I14: =E14/G14 -> 14.01699 | J14: T
B15: Per M width
A16: Total Load on Half = | D16: =I7 -> 8.316 | E16: + | F16: =I14 -> 14.01699 | H16: = | I16: =D16+F16 -> 22.33299 | J16: T
A17: of pier along bridge | I17: Per M width
A18: Effective depth of slab =90-2.5-2.5/2 = | D18: =C3*100-2.5-2.5/2 -> 71.25 | E18: cm
A19: Placement of the live load at effective depth from the support ( taking support width 750 mm)
A20: Eccentricity = 71.25 -75/2 | D20: = | E20: =D18-75/2 -> 33.75 | F20: cm | G20: = | H20: =E20/100 -> 0.3375 | I20: M
A21: Bending Moment along the bridge = | C21: =I16 -> 22.33299 | D21: x | E21: =H20 -> 0.3375 | H21: =ROUNDUP(C21*E21,2) -> 7.54 | I21: T - M/M width
B22: = | C22: =H21 -> 7.54 | D22: x | E22: 10 | F22: = | G22: =ROUNDUP(C22*10,2) -> 75.4 | H22: kN-M/M width
A23: This moment is too small hence it will not/be the governing B.M.
B24: Moment in pier cap | E24: =G22 -> 75.4 | F24: kN-m
B25: CONCRETE GRADE | E25: M30
B26: FOR THIS GRADE scbc | E26: 10 | F26: N/mm2
B27: m | E27: =280/(3*E26) -> 9.3333333
B28: sst | E28: 200
B29: factor k | E29: =(E27*E26)/(E26*E27+E28) -> 0.31818182
B30: j | E30: =1-(E29/3) -> 0.89393939
B31: R | E31: =0.5*E26*E30*E29 -> 1.4221763
B32: Effective Depth Required | E32: =SQRT((E24*1000*1000)/(E31*1000)) -> 230.25494 | F32: mm
B33: Adopt Total Depth | E33: =1200 -> 1200 | F33: mm
B34: Cover | E34: 50 | F34: mm
B35: Assume Bar Dia | E35: 25 | F35: mm
B36: Keeping A Cover Of 50 mm Effective Depth | E36: =E33-E34-E35/2 -> 1137.5 | F36: mm
B37: Adopt Effective Depth | E37: =IF(E32>E36,E32,E36) -> 1137.5 | F37: mm
B38: Steel Required Ast | E38: =(E24*1000*1000)/(E28*E30*E37) -> 370.75061 | F38: mm2
B39: Area Of One Bar | E39: =3.14*E35*E35/4 -> 490.625 | F39: mm2
B40: Spacing S | E40: =(E39*1000)/E38 -> 1323.3289 | F40: mm
...

Sheet LLOAD
A1: CALCULATION OF LIVE LOAD REACTION FOR PIER SUBSTRUCTURE
A2: FOR SIMPLY SUPPORTED SPANS OF A TWO LANE BRIDGE STRUCTURE
A4: Centre line of pier w.r.t. the bearings :-
A6: Rb | B6: = | C6: 0.3 | D6: m
A7: Rc | B7: = | C7: 0.3 | D7: m
A9: Reaction has been calculated for the following cases
A10: 1. | B10: One lane of class 70-R(W)
A11: 2. | B11: One lane of class - A
A12: 3. | B12: Two lane of class - A
A13: 4. | B13: Three lane of class - A
A14: 5. | B14: One lane of class 70-R(W) + One lane of class - A
A16: Condition A: | C16: MAXIMUM LONGITUDINAL MOMENT CASE
A18: Case 1: | B18: One lane of class 70-R(W)
D19: Cg of | E19: =VLOOKUP(span,AA27:AC39,2,0.1) -> 80
E20: =VLOOKUP(span,AA27:AC39,3,0.1) -> 3.65
A25: 0.3 | B25: m | C25: =7.6+0.375+0.375 -> 8.35 | D25: m | E25: Rb | F25: Rc | H25: =span -> 8.35 | I25: 0.3
B26: Ra | E26: 0.3 | F26: 0.3 | I26: Rd | AA26: span | AB26: load | AC26: cg
AA27: 4.42 | AB27: 51 | AC27: 1.93
B28: Rb = | C28: =CONCATENATE(E19,"*(",C25,"-",E20,"+",E26,")/",C25) -> 80*(8.35-3.65+0.3)/8.35 | H28: = | I28: =E19*(C25-E20+1.6)/C25 -> 60.359281 | J28: t | AA28: 5.79 | AB28: 68 | AC28: 2.895
B29: Rc = | H29: = | I29: 0 | J29: t | AA29: 7.92 | AB29: 80 | AC29: 3.65
B30: Ra= | H30: = | I30: =E19-I28 -> 19.640719 | J30: t
B31: Vert.Reaction= | D31: =CONCATENATE(ROUND(I28,1)," + ",ROUND(I29,1)) -> 60.4 + 0 | H31: = | I31: =I28+I29 -> 60.359281 | J31: t | AA31: 9.44 | AB31: 92 | AC31: 4.4
B32: Braking Force, B = | D32: =CONCATENATE("0.2*",E19) -> 0.2*80 | H32: = | I32: =0.2*E19 -> 16 | J32: t | AA32: 13.4 | AB32: 100 | AC32: 5.12
B33: Dead load reaction on the pier , Rg | H33: = | I33: 485 | J33: t
B35: Value of " m " = | H35: = | I35: 0
B36: Horizontal force due to temperature, T = m*(Rg+Ra) | H36: = | I36: =I35*(I33+I30) -> 0 | J36: t
B37: Design horizontal force is higher of either ( B/2+T ) or ( B-T ) | H37: = | I37: =MAX(I32/2+I36,I32-I36) -> 16 | J37: t
B38: ( neglecting shear rating of elastomeric bearing in the adjacent span, which is on the conservative side )
AA39: =$C$25+$A$25+($E$26-0.04)/2 -> 8.78
B40: CL of 70-R | F40: CL of c/w
C41: 2.595 | D41: =$E$44/2-C41 -> 1.605
E44: 8.4 | F44: m
B45: Transverse eccentricity | H45: = | I45: 2.905 | J45: m
B46: Transverse moment = | E46: =CONCATENATE(I45,"*","(",ROUND(I28,1)," + ",I29,")") -> 2.905*(60.4 + 0) | H46: = | I46: =I45*I28 -> 175.34371 | J46: t.m
B47: Long. moment = | D47: =CONCATENATE(ROUND(I28,1),"*",C6,"-",ROUND(I29,1),"*",C7) -> 60.4*0.3-0*0.3 | H47: = | I47: =I31*C6-I29*C7 -> 18.107784 | J47: t.m
B48: Long. Eccentricity ( for input) | H48: = | I48: =I47/I31 -> 0.3 | J48: m
A50: B) | B50: One lane of class-A | AC50: SPAN | AD50: LOAD | AE50: CG
D51: Cg of | E51: 55.4 | AC51: 5.5 | AD51: 29.6 | AE51: 1.73
E52: 9.7 | G52: 0 | AC52: 8.5 | AD52: 36.4 | AE52: 2.99
AC53: 11.5 | AD53: 43.2 | AE53: 4.33
...

Sheet loadsumm 
A1: Summary of Loads
A3: Max. Longitudinal Moment | F3: Design horizontal force (t) | H3: Transverse ecc. (m) | I3: Longitudinal ecc. (m)
A4: Max. vertical reaction (t) | B4: Transverse moment (t.m) | D4: Longitudinal moment (t.m)
A5: =LLOAD!I31 -> 60.359281 | B5: =LLOAD!I46 -> 175.34371 | D5: =LLOAD!I47 -> 18.107784 | F5: =LLOAD!I37 -> 16 | H5: =LLOAD!I45 -> 2.905 | I5: =LLOAD!I48 -> 0.3
A6: =LLOAD!I63 -> 55.4 | B6: =LLOAD!I77 -> 160.66 | D6: =LLOAD!I78 -> 2.0899401 | F6: =LLOAD!I68 -> 11.08 | G6: =[3]LLOAD!M63 -> #REF! | H6: =LLOAD!I76 -> 2.9 | I6: =LLOAD!I79 -> 0.037724551
A7: =LLOAD!I85 -> 13.932934 | B7: =LLOAD!I101 -> 16.022874 | D7: =LLOAD!I102 -> 4.1798802 | F7: =LLOAD!I92 -> 11.08 | G7: =[3]LLOAD!L228 -> #REF! | H7: =LLOAD!I125 -> 0.7 | I7: =LLOAD!I128 -> 0.3
A8: =LLOAD!I109 -> 18.809461 | B8: =LLOAD!I126 -> 13.166623 | D8: =LLOAD!I127 -> 5.6428383 | F8: =LLOAD!I117 -> 13.85 | G8: =[3]LLOAD!L252 -> #REF! | H8: =LLOAD!I125 -> 0.7 | I8: =LLOAD!I128 -> 0.3
A9: =LLOAD!I133 -> 60.593174 | B9: =LLOAD!I150 -> 115.92694 | D9: =LLOAD!I152 -> 18.177952 | F9: =LLOAD!I140 -> 18.77 | G9: =[3]LLOAD!L275 -> #REF! | H9: =LLOAD!I151 -> 1.9132013 | I9: =LLOAD!I153 -> 0.3
C11: Max.Transverse Moment | F11: Design horizontal force (t) | G11: Transverse ecc. (m) | H11: Longitudinal ecc. (m)
A12: Load case | C12: Max. vertical reaction (t) | D12: Transverse moment (t.m) | E12: Longitudinal moment (t.m)
A13: 1L class 70 - R | C13: =LLOAD!I173 -> 53 | D13: =LLOAD!I187 -> 153.965 | E13: =LLOAD!I188 -> 2.8426347 | F13: =LLOAD!I178 -> 20 | G13: =LLOAD!I186 -> 2.905 | H13: =LLOAD!I189 -> 0.053634618
A14: 1L class - A | C14: =LLOAD!I204 -> 34.622275 | D14: =LLOAD!I218 -> 145.41356 | E14: =LLOAD!I219 -> 4.5232096 | F14: =LLOAD!I209 -> 10 | G14: =LLOAD!I217 -> 4.2 | H14: =LLOAD!I220 -> 0.13064449
A15: 2L class - A | C15: =LLOAD!H228 -> 69.244551 | D15: =LLOAD!H242 -> 79.631234 | E15: =LLOAD!H243 -> 9.0464192 | F15: =LLOAD!H233 -> 11.08 | G15: =LLOAD!H243 -> 9.0464192 | H15: =LLOAD!H244 -> 0.13064449
A16: 3L class - A | C16: =LLOAD!H252 -> 93.480144 | D16: =LLOAD!H267 -> 65.436101 | E16: =LLOAD!H268 -> 12.212666 | F16: =LLOAD!H258 -> 13.85 | G16: =LLOAD!H266 -> 0.7 | H16: =LLOAD!H269 -> 0.13064449
A17: 1L class 70 - R + 1L class - A | C17: =LLOAD!H273+LLOAD!H274 -> 78.826635 | D17: =LLOAD!H291 -> 112.39406 | E17: =LLOAD!H293 -> 6.6292599 | F17: =LLOAD!H281 -> 18.77 | G17: =LLOAD!H292 -> 1.4258386 | H17: =LLOAD!H294 -> 0.084099238
A19: Vertical reaction due to braking has been neglected.

Sheet LL-ABSTRACT
B2: Maximum Reaction due Live Load including Impact | H2: =MAX('loadsumm '!C13,'loadsumm '!C14,'loadsumm '!C15,'loadsumm '!C17) -> 78.826635 | I2: MT | J2: = | K2: =H2*10 -> 788.26635 | L2: KN
B4: Maximum Longitudinal moment due to Live Load including Impact and Breaking Force | H4: =MAX('loadsumm '!E15,'loadsumm '!E16,'loadsumm '!E17,'loadsumm '!E19) -> 12.212666 | I4: T-M | J4: = | K4: =H4*10 -> 122.12666 | L4: KNM
B6: Maximum Transverse moment due to Live Load including Impact and Breaking Force | H6: =MAX('loadsumm '!D17,'loadsumm '!D18,'loadsumm '!D19,'loadsumm '!D21) -> 112.39406 | I6: T-M | J6: = | K6: =H6*10 -> 1123.9406 | L6: KNM

Sheet TYPE1-AbutMENT Drawing
A1: ='FOOTING DESIGN'!A2:N2 -> Name Of Work :- Construction of Submersible Bridge on ON KHERWARA - JAWAS - SUVERI ROAD IN KM 9/000, ACROSS RIVER SOM
A2: Deck Level | G2: =HYDRAULICS!E40 -> 101.6 | H2: M
A3: Foundation Level | G3: ='STABILITY CHECK FOR PIER'!E18-1+4 -> 96.47 | H3: M
A4: Thickness of Deck Slab | G4: ='Deck Anchorage'!H11*1000 -> 750 | H4: mm
A5: Thickness of Approach Slab | G5: 300 | H5: mm
A6: Height below Approach Slab | G6: =(Y14-Y31-G5/1000)*1000 -> 4830 | H6: mm
A7: Length of Heel projection | G7: =4500 -> 4500 | H7: mm | J7: Offset | K7: 1000 | L7: mm
A8: Length of Toe projection | G8: =2500 -> 2500 | H8: mm | J8: Offset | K8: 1000 | L8: mm
A9: Width of Stem | G9: 1050 | H9: mm
A10: Thickness of Abutment Cap | G10: 1200 | H10: mm
A11: Thickness of Dirt Wall | G11: 300 | H11: mm
A12: Depth of Footing | G12: 1000 | H12: mm
M13: =G11 -> 300
X14: RL | Y14: =G2 -> 101.6 | Z14: M
A15: =G5 -> 300 | F15: APPROACH SLAB
K17: =G4-G5 -> 450 | M17: DIRT WALL | Q17: DECK SLAB | W17: =G4 -> 750
J20: =G10 -> 1200 | N20: PIER CAP
B21: =G6 -> 4830
K23: =B21-K17-J20-W30 -> 2180
C28: =K7 -> 1000 | F28: HEEL | S28: TOE | U28: =K8 -> 1000
W30: =G12 -> 1000
X31: RL | Y31: =G3 -> 96.47 | Z31: M
G32: =G7 -> 4500 | O32: =G9 -> 1050 | S32: =G8 -> 2500
M33: =G32+O32+S32 -> 8050
C35: TYPICAL SECTION OF THE ABUTMENT TYPABUT-01

Sheet TYPE1-STABILITY CHECK ABUTMENT
A1: Design of ABUTMENT
A2: ='TYPE1-AbutMENT Drawing'!A1:Z1 -> Name Of Work :- Construction of Submersible Bridge on ON KHERWARA - JAWAS - SUVERI ROAD IN KM 9/000, ACROSS RIVER SOM
A3: (a) Data | B3: Preliminary dimensions | C3: : Assumed as in Fig. TYPABUT-01
B4: Superstructure | C4: : RCC Slab Bridge | D4: Total Width of Slab = | F4: 8.4 | G4: M
C5: overall length = 8.80 m
B6: Type of abutment | C6: : Reinforced concrete
B7: Loading | C7: : As for National Highway
B8: Back fill | C8: : Gravel with angle of repose Φ = | F8: 35 | G8: o
C9: Unit weight of back fill, w = | E9: 18 | F9: kN/m3
C10: Angle of internal friction of soil on wall, z = | F10: 17.5 | G10: o
B11: Approach slab | C11: : R.C. slab 300 mm thick, adequately reinforced
B12: Load from superstructure per running foot of abutment wall:
B13: Dead load | C13: = | D13: ='STABILITY CHECK FOR PIER'!P46/8.4 -> 177.84689 | E13: kN/m
B14: Live load | C14: = | D14: ='STABILITY CHECK FOR PIER'!F63/8.4 -> 93.841232 | E14: kN/m
B15: (Refer Stability Analysis for sub structure. The above two values are obtained from the calculations for superstructure, and are taken to act over a width of 15 m).
B16: Bearing : Tar Paper Bearings
A17: (C) Self weight of abutment
B18: Treating the section as composed of 6 elements as shown in Fig. 1the weight of each element and moment about the point O on the front toe are computed as in Table 1
A19: (d) Longitudinal forces
A20: (i) | B20: Force due to braking
B21: Force due to 70 R wheeled vehicle = | C21: 0.2 | D21: x | E21: 1000 | F21: = | G21: =C21*E21 -> 200 | H21: kN
B22: This force acts at 1.2 m above the road level(Clause 214.3).
B23: Force on one abutment wall = | C23: =G21 -> 200 | D23: / | E23: 2 | F23: = | G23: =C23/E23 -> 100 | H23: kN
B24: Horizontal force per m of wall = | C24: =G23 -> 100 | D24: / | E24: =F4 -> 8.4 | F24: = | G24: =ROUNDUP(C24/E24,2) -> 11.91 | H24: kN/ m
A25: (ii) | B25: Force due to temperature variation and shrinkage
B26: Assuming moderate climate, variation in temperature is taken as + | D26: 17 | E26: oC as per
B27: Clause 218.5 of Bridge Code.
B28: Coefficient of Thermal expansion = | C28: =11.7*10^-6 -> 1.17e-05 | D28: /oC
B29: Strain due to temperature variation = | C29: =D26 -> 17 | D29: x | E29: =C28 -> 1.17e-05 | F29: = | G29: =C29*E29 -> 0.0001989
B30: From Clause 220.3, strain due to concrete shrinkage = | C30: =2*10^-4 -> 0.0002
B31: Total strain due to temperature and shrinkage = | C31: =G29 -> 0.0001989 | D31: + | E31: =C30 -> 0.0002 | F31: = | G31: =E31+C31 -> 0.0003989
B32: Horizontal deformation of deck due to temperature and shrinkage affecting one abutment = | C32: =G31 -> 0.0003989 | D32: x | E32: ='STABILITY CHECK FOR PIER'!D27*1000 -> 8800 | F32: /2 = | G32: =C32*E32/2 -> 1.75516 | H32: mm
B33: Modulus of Elasticity Ec = | C33: 5000x fck1/2 | D33: = | E33: =ROUNDUP(5700*(30^0.5),2) -> 31220.19 | F33: N/mm2
B34: Horizontal Stress due to strain in longitudinal direction at bearing level = | C34: =G31 -> 0.0003989 | D34: x | E34: =E33 -> 31220.19 | F34: = | G34: =G31*E33 -> 12.453734 | H34: N/mm2
B35: Horizontal Force due to strain in longitudinal direction at bearing level (For 1 m width of Slab) = | C35: =G34 -> 12.453734 | D35: x | E35: ='STABILITY CHECK FOR PIER'!H27*1000 -> 750 | F35: = | G35: =C35*E35 -> 9340.3003 | H35: N/m
F36: = | G36: =G35/1000 -> 9.3403003 | H36: kN/m
A37: (iii) | B37: Vertical reaction due to braking
B38: 200(1.2 + 0.975)
B39: Vertical reaction at one abutment = ---------------------- | D39: = | E39: =200*(1.2+0.975)/(11.1*15) -> 2.6126126 | F39: kN/m
B40: 11.10x15
...

Sheet TYPE1-ABUTMENT FOOTING DESIGN
A1: DESIGN OF ABUTMENT FOOTING
A2: ='TYPE1-STABILITY CHECK ABUTMENT'!A2 -> Name Of Work :- Construction of Submersible Bridge on ON KHERWARA - JAWAS - SUVERI ROAD IN KM 9/000, ACROSS RIVER SOM
A3: REDISTRIBUTION OF PRESSURE
A4: FOR WIND AT SERVICE CONDITION
B5: Length of footing | C5: lf | D5: =15+'TYPE1-AbutMENT Drawing'!K7/1000+'TYPE1-AbutMENT Drawing'!K8/1000 -> 17 | E5: m
B6: Width of Footing | C6: lb | D6: ='TYPE1- Abut Footing STRESS'!D18 -> 8.05 | E6: m
B7: Width of Abutment just above footing | D7: =D6-('TYPE1-AbutMENT Drawing'!K7+'TYPE1-AbutMENT Drawing'!K8)/1000 -> 6.05 | E7: m
B8: Vertical Load | C8: P | D8: ='TYPE1-STABILITY CHECK ABUTMENT'!C134 -> 1004.041 | E8: kN
B9: Longitudinal Moment | C9: Me | D9: ='TYPE1-STABILITY CHECK ABUTMENT'!G136 -> 3661.123 | E9: kN-m
B10: Transverse Moment | C10: Mb | D10: 0 | E10: kN-m
B11: el | C11: = Me/P | D11: =D9/D8 -> 3.6463879 | E11: m
B12: eb | C12: = Mb/P | D12: =D10/D8 -> 0 | E12: m
B13: el/lf | D13: =D11/D5 -> 0.21449341 | E13: Refer VK Raina "Concrete Bridge Practice : Analysis, Design and Economics " Chapter 14 "Evaluation of Base Presssure and Contact Area" Fig 14.2 & 14.3
B14: eb/lb | D14: =D12/D6 -> 0
B15: K | D15: 1
B16: y | D16: 0
B17: Area in Tension = y x lb | E17: =D6*D16 -> 0 | F17: m2 | G17: =E17/D6*100 -> 0 | H17: %
B18: Maximum Pressure before Redistribution | E18: ='TYPE1-STABILITY CHECK ABUTMENT'!F100 -> 160.06 | F18: kN/m2
B19: Maximum Pressure After Redistribution = pxK | E19: =E18*D15 -> 160.06 | F19: kN/m2
B20: Maximum Stress at Edge of Pier | E20: =E19 -> 160.06 | F20: kN/m2
B21: Distance From Face of Pier to the Edge | E21: ='TYPE1- Abut Footing STRESS'!F8 -> 1 | F21: m
B22: Stress at the Edge of Pier | E22: =(D6-E17-E21)*E20/(D6-E17) -> 140.17677 | F22: kN/m2
B23: Average Stress on Cantilevered Area | E23: =(E20+E22)/2 -> 150.11839 | F23: kN/m2
B24: Area of the Cantilever Portion | E24: =E21*1 -> 1 | F24: m2
B25: Distance of Centroid of the Stress in Cantilever Portion | E25: =E21/3*(E22+2*E20)/(E20+E22) -> 0.51103753 | F25: m
B26: Moment about the Face of Pier | E26: =E23*E24*E25 -> 76.716128 | F26: kN-m
B27: CONCRETE GRADE | E27: M-25
B28: FOR THIS GRADE scbc | E28: 10 | F28: N/mm2
B29: m | E29: =280/(3*E28) -> 9.3333333
B30: sst | E30: 200
B31: factor k | E31: =(E29*E28)/(E28*E29+E30) -> 0.31818182
B32: j | E32: =1-(E31/3) -> 0.89393939
B33: R | E33: =0.5*E28*E32*E31 -> 1.4221763
B34: Effective Depth Required | E34: =SQRT((E26*1000*1000)/(E33*1000)) -> 232.25583 | F34: mm
B35: Adopt Total Depth | E35: 1000 | F35: mm
B36: Cover | E36: 50 | F36: mm
B37: Assume Bar Dia | E37: 16 | F37: mm
B38: Keeping A Cover Of 50 mm Effective Depth | E38: =E35-E36-E37/2 -> 942 | F38: mm
B39: Adopt Effective Depth | E39: =IF(E34>E38,E34,E38) -> 942 | F39: mm
B40: Steel Required Ast | E40: =(E26*1000*1000)/(E30*E32*E39) -> 455.50978 | F40: mm2
...

Sheet TYPE1- Abut Footing STRESS
E1: =D18-1 -> 7.05 | F1: m
B8: ='TYPE1-AbutMENT Drawing'!K7/1000 -> 1 | C8: m | F8: ='TYPE1-AbutMENT Drawing'!K8/1000 -> 1 | G8: m
D18: ='TYPE1-AbutMENT Drawing'!M33/1000 -> 8.05 | E18: m
B21: 258.56357 | C21: m
E25: ='TYPE1-ABUTMENT FOOTING DESIGN'!E56 -> 157.48126
E26: kN/m2 | G26: ='TYPE1-ABUTMENT FOOTING DESIGN'!E55 -> 160.06 | H26: kN/m2
D29: STRESS DIAGRAM
A31: DESIGN OF ABUTMENT FOOTING

Sheet TYPE1-STEEL IN ABUTMENT
A1: REINFORCEMENT CALCULATION IN ABUTMENT SUBMERSIBLE BRIDGE
A2: ='TYPE1-STABILITY CHECK ABUTMENT'!A2 -> Name Of Work :- Construction of Submersible Bridge on ON KHERWARA - JAWAS - SUVERI ROAD IN KM 9/000, ACROSS RIVER SOM
A3: Minimum Shrinkage and Temperature reinforcement required as per Clause 305.10 IRC 21-2000
A4: in any RC structure is 250 Sq mm per m in each direction. Allowable maximum spacing is 300 mm.
B5: Shrinkage and Temperature reinforcement required per metre = | E5: 250 | F5: mm2
B6: Area Of One Bar | C6: 12 | D6: mm dia | E6: =3.14*C6*C6/4 -> 113.04 | F6: mm2
B7: Spacing S | E7: =(E6*1000)/E5 -> 452.16 | F7: mm
B8: Provide Bars Of Dia And Spacing | C8: =C6 -> 12 | D8: mm | E8: 125 | F8: mm
B9: Provide Bars Of Dia And Spacing | C9: =C8 -> 12 | D9: mm | E9: 125 | F9: mm
B10: HORIZONTAL SHRINKAGE &TEMPERATURE REINFORCEMENT | D10: 12 | E10: MM BARS | F10: =E8 -> 125 | G10: MM | H10: In Vertical direction on all FOUR faces
B11: VERTICAL SHRINKAGE &TEMPERATURE REINFORCEMENT | D11: 12 | E11: MM BARS | F11: =F10 -> 125 | G11: MM | H11: In Lateral direction on all FOUR faces

Sheet TYPE1-Abutment Cap
B1: DESIGN OF Abutment CAP SUBMERSIBLE BRIDGE
A2: ='TYPE1-STABILITY CHECK ABUTMENT'!A2 -> Name Of Work :- Construction of Submersible Bridge on ON KHERWARA - JAWAS - SUVERI ROAD IN KM 9/000, ACROSS RIVER SOM
A3: DESIGN OF Abutment CAP :-
A4: D.L./ M Width along bridge
A5: DL. Of Slab = | C5: 0.975 | D5: x | E5: 15 | F5: x. | G5: 2.4 | H5: = | I5: =C5*E5*G5 -> 35.1 | J5: T
A6: D.L. of Wearing coat = | C6: 0.075 | D6: x | E6: 12 | F6: x. | G6: 2.4 | H6: = | I6: =C6*E6*G6 -> 2.16 | J6: T
G7: TOTAL | I7: =SUM(I5:I6) -> 37.26 | J7: T
A8: D.L. of Slab & Wearing coat on half of the Abutment | E8: =
E9: =I7 -> 37.26 | F9: / | G9: 2 | H9: = | I9: =E9/G9 -> 18.63 | J9: T
A10: L.L. on Abutment cap including impact along bridge
D11: = | E11: 82.5 | F11: x | G11: 1.1375 | H11: = | I11: =E11*G11 -> 93.84375 | J11: T
A12: (Refer Live Load Computation)
A13: Dispersion width across the span for
A14: 70 T TRACKED VEHTCLE | D14: = | E14: 6.695 | F14: M
A15: ( Refer Solid slab design page SS-16)
A16: Live Load u.d.l. on Abutment | D16: = | E16: =I11 -> 93.84375 | F16: / | G16: =E14 -> 6.695 | H16: = | I16: =E16/G16 -> 14.01699 | J16: T
B17: Per M width
A18: Total Load on Half = | D18: =I9 -> 18.63 | E18: + | F18: =I16 -> 14.01699 | H18: = | I18: =D18+F18 -> 32.64699 | J18: T
A19: of Abutment along bridge | I19: Per M width
A20: Effective depth of slab =90-2.5-2.5/2 = | D20: =90-2.5-1.25 -> 86.25 | E20: cm
A21: Placement of the live load at effective depth from the support ( taking support width 750 mm)
A22: Eccentricity = 71.25 -75/2 | D22: = | E22: =71.25-37.5 -> 33.75 | F22: cm | G22: = | H22: =E22/100 -> 0.3375 | I22: M
A23: Bending Moment along the bridge = | C23: =I18 -> 32.64699 | D23: x | E23: =H22 -> 0.3375 | H23: =ROUNDUP(C23*E23,2) -> 11.02 | I23: T - M/M width
